Workbook

Sheet Premisas
A1: PREMISAS MACROECONOMICAS
B2: 2025 | C2: =B2+1 -> 2026 | D2: =C2+1 -> 2027 | E2: =D2+1 -> 2028 | F2: =E2+1 -> 2029 | G2: =F2+1 -> 2030 | H2: =G2+1 -> 2031 | I2: =H2+1 -> 2032 | J2: =I2+1 -> 2033 | ... L2: =K2+1 -> 2035
A3: Tipo de cambio al cierre (dolares) | B3: 16.66 | C3: 9.35 | D3: 9.95 | E3: 10.45 | F3: 11.2 | G3: 12 | H3: 12.3 | I3: 12.3 | J3: 12.3 | K3: 12.3 | L3: 12.3
A4: Tasa lider nacional. | B4: 0.16 | C4: 0.3 | D4: 0.28 | E4: 0.21 | F4: 0.18 | G4: 0.16 | H4: 0.15 | I4: 0.15 | J4: 0.15 | K4: 0.15 | L4: 0.15
A5: CPP | B5: 0.28 | C5: 0.28 | D5: 0.27 | E5: 0.27 | F5: 0.28 | G5: 0.24 | H5: 0.25 | I5: 0.25 | J5: 0.25 | K5: 0.25 | L5: 0.25
A6: CETES | B6: 0.332 | C6: 0.287 | D6: 0.28 | E6: 0.283 | F6: 0.272 | G6: 0.27 | H6: 0.268 | I6: 0.268 | J6: 0.26 | K6: 0.268 | L6: 0.26
A7: LIBOR | B7: 0.077 | C7: 0.079 | D7: 0.076 | E7: 0.072 | F7: 0.0685 | G7: 0.069 | H7: 0.073 | I7: 0.073 | J7: 0.073 | K7: 0.073 | L7: 0.073
B11: 2025 | C11: =B11+1 -> 2026 | D11: =C11+1 -> 2027 | E11: =D11+1 -> 2028 | F11: =E11+1 -> 2029 | G11: =F11+1 -> 2030 | H11: =G11+1 -> 2031 | I11: =H11+1 -> 2032 | J11: =I11+1 -> 2033 | ... L11: =K11+1 -> 2035
A12: Inflación Nacional | B12: 0.043 | C12: 0.034 | D12: 0.034 | E12: 0.034 | F12: 0.034 | G12: 0.034 | H12: 0.034 | I12: 0.034 | J12: 0.034 | K12: 0.034 | L12: 0.034
A13: Tasa ISR | B13: 0.34 | C13: 0.34 | D13: 0.34 | E13: 0.34 | F13: 0.34 | G13: 0.34 | H13: 0.34 | I13: 0.34 | J13: 0.34 | K13: 0.34 | L13: 0.34
A14: Tasa IMPAC | B14: 1.8 | C14: 1.8 | D14: 1.8 | E14: 1.8 | F14: 1.8 | G14: 1.8 | H14: 1.8 | I14: 1.8 | J14: 1.8 | K14: 1.8 | L14: 1.8
A15: Tasa de PTU | B15: 0.1 | C15: 0.1 | D15: 0.1 | E15: 0.1 | F15: 0.1 | G15: 0.1 | H15: 0.1 | I15: 0.1 | J15: 0.1 | K15: 0.1 | L15: 0.1
A16: Inflación Extranjera
A19: POLITICAS. | B19: 2025 | C19: =B19+1 -> 2026 | D19: =C19+1 -> 2027 | E19: =D19+1 -> 2028 | F19: =E19+1 -> 2029 | G19: =F19+1 -> 2030 | H19: =G19+1 -> 2031 | I19: =H19+1 -> 2032 | J19: =I19+1 -> 2033 | ... L19: =K19+1 -> 2035
A20: Porcentaje de Inventario. | B20: 0.2 | C20: 0.2 | D20: 0.2 | E20: 0.2 | F20: 0.2 | G20: 0.2 | H20: 0.2 | I20: 0.2 | J20: 0.2 | K20: 0.2 | L20: 0.2
A21: Porcentaje de proveedores. | B21: 0.2 | C21: 0.2 | D21: 0.2 | E21: 0.2 | F21: 0.2 | G21: 0.2 | H21: 0.2 | I21: 0.2 | J21: 0.2 | K21: 0.2 | L21: 0.2
A22: Porcentaje de pasivo corto plazo. | B22: 0.03 | C22: 0.03 | D22: 0.03 | E22: 0.03 | F22: 0.03 | G22: 0.03 | H22: 0.03 | I22: 0.03 | J22: 0.03 | K22: 0.03 | L22: 0.03
A23: Porcentaje de costo directo del producto. | B23: 0.15 | C23: 0.1 | D23: 0.1 | E23: 0.1 | F23: 0.1 | G23: 0.05 | H23: 0.05 | I23: 0.05 | J23: 0.05 | K23: 0.05 | L23: 0.05
A24: Porcentaje de costo indirecto del producto. | B24: 0.05 | C24: 0.05 | D24: 0.05 | E24: 0.05 | F24: 0.05 | G24: 0.05 | H24: 0.05 | I24: 0.05 | J24: 0.05 | K24: 0.05 | L24: 0.05
A25: Porcentaje de gasto de venta | B25: 0.002 | C25: 0.002 | D25: 0.002 | E25: 0.002 | F25: 0.002 | G25: 0.002 | H25: 0.002 | I25: 0.002 | J25: 0.002 | K25: 0.002 | L25: 0.002
A26: Porcentaje de administración | B26: 0.005 | C26: 0.005 | D26: 0.005 | E26: 0.005 | F26: 0.005 | G26: 0.005 | H26: 0.005 | I26: 0.005 | J26: 0.005 | K26: 0.005 | L26: 0.005
A27: Porcentaje depreciación Edificios | B27: 0.05 | C27: 0.05 | D27: 0.05 | E27: 0.05 | F27: 0.05 | G27: 0.05 | H27: 0.05 | I27: 0.05 | J27: 0.05 | K27: 0.05 | L27: 0.05
A28: Porcentaje depreciación Maquinaria y Equipo | B28: 0.1 | C28: 0.1 | D28: 0.1 | E28: 0.1 | F28: 0.1 | G28: 0.1 | H28: 0.1 | I28: 0.1 | J28: 0.1 | K28: 0.1 | L28: 0.1
A29: Porcentaje depreciación Equipo de Transporte | B29: 0.2 | C29: 0.2 | D29: 0.2 | E29: 0.2 | F29: 0.2 | G29: 0.2 | H29: 0.2 | I29: 0.2 | J29: 0.2 | K29: 0.2 | L29: 0.2
A30: Porcentaje depreciación Equipo de computo | B30: 0.085 | C30: 0.085 | D30: 0.085 | E30: 0.085 | F30: 0.085 | G30: 0.085 | H30: 0.085 | I30: 0.085 | J30: 0.085 | K30: 0.085 | L30: 0.085

Sheet COs
A1: Calculo de la Demanda basada en Ordenes de Compra (CO) históricas de clientes
A2: Producto
B4: % | E4: Año Cero | F4: 1 | G4: 2 | H4: 3 | I4: 4 | J4: 5 | K4: 6 | L4: 7 | M4: 8 | N4: 9 | O4: 10
A5: Mes | C5: =D5-1 -> 2023 | D5: =E5-1 -> 2024 | E5: 2025 | F5: =E5+1 -> 2026 | G5: =F5+1 -> 2027 | H5: =G5+1 -> 2028 | I5: =H5+1 -> 2029 | J5: =I5+1 -> 2030 | K5: =J5+1 -> 2031 | L5: =K5+1 -> 2032 | M5: =L5+1 -> 2033 | ... O5: =N5+1 -> 2035
A6: Enero | B6: 0.08 | C6: =B6*$C$18 -> 5600 | D6: =B6*$C$18 -> 5600 | E6: 0 | F6: =B6*$F$18 -> 6790.48 | G6: =B6*$G$18 -> 7265.84 | H6: =B6*$H$18 -> 7774.4 | I6: =B6*$I$18 -> 8318.48 | J6: =B6*$J$18 -> 8900.96 | K6: =B6*$K$18 -> 9524 | L6: =B6*$L$18 -> 10190.72 | M6: =B6*$M$18 -> 10945.92 | N6: =B6*$N$18 -> 11297.84 | O6: =B6*$O$18 -> 11970.72
A7: Febrero | B7: 0.06 | C7: =B7*$C$18 -> 4200 | D7: =B7*$C$18 -> 4200 | E7: 0 | F7: =B7*$F$18 -> 5092.86 | G7: =B7*$G$18 -> 5449.38 | H7: =B7*$H$18 -> 5830.8 | I7: =B7*$I$18 -> 6238.86 | J7: =B7*$J$18 -> 6675.72 | K7: =B7*$K$18 -> 7143 | L7: =B7*$L$18 -> 7643.04 | M7: =B7*$M$18 -> 8209.44 | N7: =B7*$N$18 -> 8473.38 | O7: =B7*$O$18 -> 8978.04
A8: Marzo | B8: 0.05 | C8: =B8*$C$18 -> 3500 | D8: =B8*$C$18 -> 3500 | E8: 0 | F8: =B8*$F$18 -> 4244.05 | G8: =B8*$G$18 -> 4541.15 | H8: =B8*$H$18 -> 4859 | I8: =B8*$I$18 -> 5199.05 | J8: =B8*$J$18 -> 5563.1 | K8: =B8*$K$18 -> 5952.5 | L8: =B8*$L$18 -> 6369.2 | M8: =B8*$M$18 -> 6841.2 | N8: =B8*$N$18 -> 7061.15 | O8: =B8*$O$18 -> 7481.7
A9: Abril | B9: 0.05 | C9: =B9*$C$18 -> 3500 | D9: =B9*$C$18 -> 3500 | E9: 0 | F9: =B9*$F$18 -> 4244.05 | G9: =B9*$G$18 -> 4541.15 | H9: =B9*$H$18 -> 4859 | I9: =B9*$I$18 -> 5199.05 | J9: =B9*$J$18 -> 5563.1 | K9: =B9*$K$18 -> 5952.5 | L9: =B9*$L$18 -> 6369.2 | M9: =B9*$M$18 -> 6841.2 | N9: =B9*$N$18 -> 7061.15 | O9: =B9*$O$18 -> 7481.7
A10: Mayo | B10: 0.06 | C10: =B10*$C$18 -> 4200 | D10: =B10*$C$18 -> 4200 | E10: 0 | F10: =B10*$F$18 -> 5092.86 | G10: =B10*$G$18 -> 5449.38 | H10: =B10*$H$18 -> 5830.8 | I10: =B10*$I$18 -> 6238.86 | J10: =B10*$J$18 -> 6675.72 | K10: =B10*$K$18 -> 7143 | L10: =B10*$L$18 -> 7643.04 | M10: =B10*$M$18 -> 8209.44 | N10: =B10*$N$18 -> 8473.38 | O10: =B10*$O$18 -> 8978.04
A11: Junio | B11: 0.07 | C11: =B11*$C$18 -> 4900 | D11: =B11*$C$18 -> 4900 | E11: 0 | F11: =B11*$F$18 -> 5941.67 | G11: =B11*$G$18 -> 6357.61 | H11: =B11*$H$18 -> 6802.6 | I11: =B11*$I$18 -> 7278.67 | J11: =B11*$J$18 -> 7788.34 | K11: =B11*$K$18 -> 8333.5 | L11: =B11*$L$18 -> 8916.88 | M11: =B11*$M$18 -> 9577.68 | N11: =B11*$N$18 -> 9885.61 | O11: =B11*$O$18 -> 10474.38
A12: Julio | B12: 0.07 | C12: =B12*$C$18 -> 4900 | D12: =B12*$C$18 -> 4900 | E12: 0 | F12: =B12*$F$18 -> 5941.67 | G12: =B12*$G$18 -> 6357.61 | H12: =B12*$H$18 -> 6802.6 | I12: =B12*$I$18 -> 7278.67 | J12: =B12*$J$18 -> 7788.34 | K12: =B12*$K$18 -> 8333.5 | L12: =B12*$L$18 -> 8916.88 | M12: =B12*$M$18 -> 9577.68 | N12: =B12*$N$18 -> 9885.61 | O12: =B12*$O$18 -> 10474.38
A13: Agosto | B13: 0.08 | C13: =B13*$C$18 -> 5600 | D13: =B13*$C$18 -> 5600 | E13: 0 | F13: =B13*$F$18 -> 6790.48 | G13: =B13*$G$18 -> 7265.84 | H13: =B13*$H$18 -> 7774.4 | I13: =B13*$I$18 -> 8318.48 | J13: =B13*$J$18 -> 8900.96 | K13: =B13*$K$18 -> 9524 | L13: =B13*$L$18 -> 10190.72 | M13: =B13*$M$18 -> 10945.92 | N13: =B13*$N$18 -> 11297.84 | O13: =B13*$O$18 -> 11970.72
A14: Septiembre | B14: 0.11 | C14: =B14*$C$18 -> 7700 | D14: =B14*$C$18 -> 7700 | E14: 0 | F14: =B14*$F$18 -> 9336.91 | G14: =B14*$G$18 -> 9990.53 | H14: =B14*$H$18 -> 10689.8 | I14: =B14*$I$18 -> 11437.91 | J14: =B14*$J$18 -> 12238.82 | K14: =B14*$K$18 -> 13095.5 | L14: =B14*$L$18 -> 14012.24 | M14: =B14*$M$18 -> 15050.64 | N14: =B14*$N$18 -> 15534.53 | O14: =B14*$O$18 -> 16459.74
A15: Octubre | B15: 0.06 | C15: =B15*$C$18 -> 4200 | D15: =B15*$C$18 -> 4200 | E15: 2000 | F15: =B15*$F$18 -> 5092.86 | G15: =B15*$G$18 -> 5449.38 | H15: =B15*$H$18 -> 5830.8 | I15: =B15*$I$18 -> 6238.86 | J15: =B15*$J$18 -> 6675.72 | K15: =B15*$K$18 -> 7143 | L15: =B15*$L$18 -> 7643.04 | M15: =B15*$M$18 -> 8209.44 | N15: =B15*$N$18 -> 8473.38 | O15: =B15*$O$18 -> 8978.04
A16: Noviembre | B16: 0.13 | C16: =B16*$C$18 -> 9100 | D16: =B16*$C$18 -> 9100 | E16: 6000 | F16: =B16*$F$18 -> 11034.53 | G16: =B16*$G$18 -> 11806.99 | H16: =B16*$H$18 -> 12633.4 | I16: =B16*$I$18 -> 13517.53 | J16: =B16*$J$18 -> 14464.06 | K16: =B16*$K$18 -> 15476.5 | L16: =B16*$L$18 -> 16559.92 | M16: =B16*$M$18 -> 17787.12 | N16: =B16*$N$18 -> 18358.99 | O16: =B16*$O$18 -> 19452.42
A17: Diciembre | B17: 0.18 | C17: =B17*$C$18 -> 12600 | D17: =B17*$C$18 -> 12600 | E17: 8000 | F17: =B17*$F$18 -> 15278.58 | G17: =B17*$G$18 -> 16348.14 | H17: =B17*$H$18 -> 17492.4 | I17: =B17*$I$18 -> 18716.58 | J17: =B17*$J$18 -> 20027.16 | K17: =B17*$K$18 -> 21429 | L17: =B17*$L$18 -> 22929.12 | M17: =B17*$M$18 -> 24628.32 | N17: =B17*$N$18 -> 25420.14 | O17: =B17*$O$18 -> 26934.12
A18: Total | B18: =SUM(B6:B17) -> 1 | C18: 70000 | D18: 66800 | E18: =SUM(E6:E17) -> 16000 | F18: 84881 | G18: 90823 | H18: 97180 | I18: 103981 | J18: 111262 | K18: 119050 | L18: 127384 | M18: 136824 | N18: 141223 | O18: 149634
A20: Grafico Demanda Anual

Sheet Capacidad
D2: Capacity line | E2: =E15 -> 2025 | F2: =F15 -> 2026 | G2: =G15 -> 2027 | H2: =H15 -> 2028 | I2: =I15 -> 2029 | J2: =J15 -> 2030 | K2: =K15 -> 2031 | L2: =L15 -> 2032 | ... O2: =O15 -> 2035
D3: Quality yield | E3: 0.8 | F3: 0.85 | G3: 0.9 | H3: 0.9 | I3: 0.9 | J3: 0.9 | K3: 0.9 | L3: 0.9 | M3: 0.9 | N3: 0.9 | O3: 0.9
D4: Seconds x unit | E4: 420 | F4: =F36 -> 40 | G4: =G36 -> 40 | H4: =H36 -> 40 | I4: =I36 -> 40 | J4: =J36 -> 40 | K4: =K36 -> 40 | L4: =L36 -> 40 | M4: =M36 -> 40 | ... O4: =O36 -> 40
D5: Units x hour | E5: =3600/E4 -> 8.5714286 | F5: =3600/F4 -> 90 | G5: =3600/G4 -> 90 | H5: =3600/H4 -> 90 | I5: =3600/I4 -> 90 | J5: =3600/J4 -> 90 | K5: =3600/K4 -> 90 | L5: =3600/L4 -> 90 | ... O5: =3600/O4 -> 90
D6: Hours Shift | E6: 7.5 | F6: 7.5 | G6: 7.5 | H6: 7.5 | I6: 7.5 | J6: 7.5 | K6: 7.5 | L6: 7.5 | M6: 7.5 | N6: 7.5 | O6: 7.5
D7: Shifts | E7: 2 | F7: 1 | G7: 1 | H7: 1 | I7: 1 | J7: 1 | K7: 1 | L7: 1 | M7: 1 | N7: 1 | O7: 1
D8: Production Lines | E8: 1 | F8: 1 | G8: 1 | H8: 1 | I8: 2 | J8: 1 | K8: 1 | L8: 1 | M8: 1 | N8: 1 | O8: 1
D9: Week working days | E9: 5 | F9: 5 | G9: 5 | H9: 5 | I9: 5 | J9: 5 | K9: 5 | L9: 5 | M9: 6 | N9: 6 | O9: 6
D10: Months working weeks | E10: 4 | F10: 4 | G10: 4 | H10: 4 | I10: 4 | J10: 4 | K10: 4 | L10: 4 | M10: 4 | N10: 4 | O10: 4
D11: Year working months | E11: 12 | F11: 12 | G11: 12 | H11: 12 | I11: 12 | J11: 12 | K11: 12 | L11: 12 | M11: 12 | N11: 12 | O11: 12
D12: Anual Capacity | E12: =E5*E6*E7*E8*E9*E10*E11 -> 30857.143 | F12: =F5*F6*F7*F8*F9*F10*F11 -> 162000 | G12: =G5*G6*G7*G8*G9*G10*G11 -> 162000 | H12: =H5*H6*H7*H8*H9*H10*H11 -> 162000 | I12: =I5*I6*I7*I8*I9*I10*I11 -> 324000 | J12: =J5*J6*J7*J8*J9*J10*J11 -> 162000 | K12: =K5*K6*K7*K8*K9*K10*K11 -> 162000 | L12: =L5*L6*L7*L8*L9*L10*L11 -> 162000 | ... O12: =O5*O6*O7*O8*O9*O10*O11 -> 194400
E13: =E12*25%*4 -> 30857.143 | F13: =F12*25%*4 -> 162000 | G13: =G12*25%*4 -> 162000 | H13: =H12*25%*4 -> 162000 | I13: =I12*25%*4 -> 324000 | J13: =J12*25%*4 -> 162000 | K13: =K12*25%*4 -> 162000 | L13: =L12*25%*4 -> 162000 | ... O13: =O12*25%*4 -> 194400
E15: =COs!E5 -> 2025 | F15: =E15+1 -> 2026 | G15: =F15+1 -> 2027 | H15: =G15+1 -> 2028 | I15: =H15+1 -> 2029 | J15: =I15+1 -> 2030 | K15: =J15+1 -> 2031 | L15: =K15+1 -> 2032 | M15: =L15+1 -> 2033 | ... O15: =N15+1 -> 2035
D16: CO | E16: =COs!E18 -> 16000 | F16: =COs!F18 -> 84881 | G16: =COs!G18 -> 90823 | H16: =COs!H18 -> 97180 | I16: =COs!I18 -> 103981 | J16: =COs!J18 -> 111262 | K16: =COs!K18 -> 119050 | L16: =COs!L18 -> 127384 | ... P16: =COs!P18 -> 0
D17: WO | E17: =E16/E3 -> 20000 | F17: =F16/F3 -> 99860 | G17: =G16/G3 -> 100914.44 | H17: =H16/H3 -> 107977.78 | I17: =I16/I3 -> 115534.44 | J17: =J16/J3 -> 123624.44 | K17: =K16/K3 -> 132277.78 | L17: =L16/L3 -> 141537.78 | ... O17: =O16/O3 -> 166260
D18: Capacidad Ocupada | E18: =E17/E13 -> 0.64814815 | F18: =F17/F13 -> 0.61641975 | G18: =G17/G13 -> 0.62292867 | H18: =H17/H13 -> 0.66652949 | I18: =I17/I13 -> 0.35658779 | J18: =J17/J13 -> 0.76311385 | K18: =K17/K13 -> 0.81652949 | L18: =L17/L13 -> 0.87368999 | ... O18: =O17/O13 -> 0.85524691
A20: Linea | B20: Descripción | C20: Tiempo en segundos de cada proceso | D20: Operadores necesarios | E20: Tiempo de ciclo | F20: Tpo Proceso | G20: Tpo Proceso | H20: Tpo Proceso | I20: Tpo Proceso | J20: Tpo Proceso | K20: Tpo Proceso | L20: Tpo Proceso | M20: Tpo Proceso | N20: Tpo Proceso | O20: Tpo Proceso
A21: Op1 | B21: Elaboración placa base | C21: 60 | D21: 6 | E21: =C21/D21 -> 10 | F21: =C21/D21 -> 10 | G21: 100 | H21: 100 | I21: 100 | J21: 100 | K21: 100 | L21: 100 | M21: 100 | N21: 100 | O21: 100
A22: OP2 | B22: Ensamble base | C22: 12 | D22: 1 | E22: =C22/D22 -> 12 | F22: =C22/D22 -> 12 | G22: 12 | H22: 12 | I22: 12 | J22: 12 | K22: 12 | L22: 12 | M22: 12 | N22: 12 | O22: 12
A23: Op3 | B23: Ensamble 2 | C23: 12 | D23: 1 | E23: =C23/D23 -> 12 | F23: =C23/D23 -> 12 | G23: 12 | H23: 12 | I23: 12 | J23: 12 | K23: 12 | L23: 12 | M23: 12 | N23: 12 | O23: 12
A24: Op4 | B24: Ensamble 3 | C24: 12 | D24: 1 | E24: =C24/D24 -> 12 | F24: =C24/D24 -> 12 | G24: 12 | H24: 12 | I24: 12 | J24: 12 | K24: 12 | L24: 12 | M24: 12 | N24: 12 | O24: 12
A25: Op5 | B25: Ensamble 4 | C25: 12 | D25: 1 | E25: =C25/D25 -> 12 | F25: =C25/D25 -> 12 | G25: 12 | H25: 12 | I25: 12 | J25: 12 | K25: 12 | L25: 12 | M25: 12 | N25: 12 | O25: 12
A26: Op6 | B26: Ensamble 5 | C26: 12 | D26: 1 | E26: =C26/D26 -> 12 | F26: =C26/D26 -> 12 | G26: 12 | H26: 12 | I26: 12 | J26: 12 | K26: 12 | L26: 12 | M26: 12 | N26: 12 | O26: 12
A27: Op7 | B27: Ensamble 6 | C27: 12 | D27: 1 | E27: =C27/D27 -> 12 | F27: =C27/D27 -> 12 | G27: 12 | H27: 12 | I27: 12 | J27: 12 | K27: 12 | L27: 12 | M27: 12 | N27: 12 | O27: 12
A28: Op8 | B28: Ensamble 7 | C28: 12 | D28: 1 | E28: =C28/D28 -> 12 | F28: =C28/D28 -> 12 | G28: 12 | H28: 12 | I28: 12 | J28: 12 | K28: 12 | L28: 12 | M28: 12 | N28: 12 | O28: 12
A29: Op9 | B29: Ensamble 8 | C29: 12 | D29: 1 | E29: =C29/D29 -> 12 | F29: =C29/D29 -> 12 | G29: 12 | H29: 12 | I29: 12 | J29: 12 | K29: 12 | L29: 12 | M29: 12 | N29: 12 | O29: 12
A30: Op10 | B30: Ensamble 9 | C30: 12 | D30: 1 | E30: =C30/D30 -> 12 | F30: =C30/D30 -> 12 | G30: 12 | H30: 12 | I30: 12 | J30: 12 | K30: 12 | L30: 12 | M30: 12 | N30: 12 | O30: 12
A31: Op11 | B31: Ensamble 10 | C31: 12 | D31: 1 | E31: =C31/D31 -> 12 | F31: =C31/D31 -> 12 | G31: 12 | H31: 12 | I31: 12 | J31: 12 | K31: 12 | L31: 12 | M31: 12 | N31: 12 | O31: 12
A32: Op12 | B32: Ensamble 11 | C32: 12 | D32: 1 | E32: =C32/D32 -> 12 | F32: =C32/D32 -> 12 | G32: 12 | H32: 12 | I32: 12 | J32: 12 | K32: 12 | L32: 12 | M32: 12 | N32: 12 | O32: 12
... A35: Op15 | B35: Ensamble 14 | C35: 12 | D35: 1 | E35: =C35/D35 -> 12 | F35: =C35/D35 -> 12 | G35: 12 | H35: 12 | I35: 12 | J35: 12 | K35: 12 | L35: 12 | M35: 12 | N35: 12 | O35: 12
A36: Op16 | B36: Ensamble 15 | C36: 120 | D36: 3 | E36: =C36/D36 -> 40 | F36: =E36 -> 40 | G36: =F36 -> 40 | H36: =G36 -> 40 | I36: =H36 -> 40 | J36: =I36 -> 40 | K36: =J36 -> 40 | L36: =K36 -> 40 | M36: =L36 -> 40 | ... O36: =N36 -> 40
C37: Operadores | D37: =SUM(D21:D36) -> 23 | E37: =SUM(E21:E36) -> 218
A39: Personal Mano de Obra Directa
A41: Operadores | C41: =D37 -> 23
A42: Supervisores | C42: 2
A45: Graficos

Sheet BOM
B3: DN001 | C3: Dron Super Sport
B4: Costo de Materia Prima | D4: =F26 -> 6121.03
B5: Costo de venta | D5: 7600
B8: Id | C8: Descripción | D8: Cantidad | E8: Costo | F8: Sub total | G8: Sxrap
A9: 1 | B9: FR001 | C9: Base del frame | D9: 1 | E9: 627 | F9: =D9*E9 -> 627 | G9: 1
A10: 2 | B10: FR005 | C10: Placa inferior del frame | D10: 1 | E10: 214.5 | F10: =D10*E10 -> 214.5 | G10: 1
A11: 3 | B11: FR003 | C11: Brazos del dron | D11: 4 | E11: 20 | F11: =D11*E11 -> 80 | G11: 1
A12: 4 | B12: FR006 | C12: Placa superior para batería | D12: 1 | E12: 257 | F12: =D12*E12 -> 257 | G12: 1
A13: 5 | B13: FR004 | C13: Placa superior del frame | D13: 1 | E13: 214.5 | F13: =D13*E13 -> 214.5 | G13: 1
A14: 6 | B14: AC001 | C14: Soporte del Buzzer | D14: 1 | E14: 0.49 | F14: =D14*E14 -> 0.49 | G14: 1
A15: 7 | B15: AC003 | C15: Soporte del capacitor | D15: 1 | E15: 0.46 | F15: =D15*E15 -> 0.46 | G15: 1
A16: 8 | B16: AC004 | C16: Parachoques frontal | D16: 1 | E16: 0.84 | F16: =D16*E16 -> 0.84 | G16: 1
A17: 9 | B17: AC005 | C17: Soporte para GoPro | D17: 1 | E17: 12.92 | F17: =D17*E17 -> 12.92 | G17: 1
A18: 10 | B18: AC006 | C18: Amortiguador de motor | D18: 4 | E18: 0.68 | F18: =D18*E18 -> 2.72 | G18: 1
A19: 11 | B19: AC007 | C19: Parachoques trasero | D19: 1 | E19: 0.84 | F19: =D19*E19 -> 0.84 | G19: 0.8
A20: 12 | B20: AC008 | C20: Soporte para antena | D20: 1 | E20: 3.84 | F20: =D20*E20 -> 3.84 | G20: 1
... A25: 17 | B25: SE003 | C25: Sistema electrónico | D25: 1 | E25: 4500 | F25: =D25*E25 -> 4500 | G25: 1
F26: =SUM(F9:F25) -> 6121.03

Sheet Depreciación.
B2: Cédula para calcular las depreciaciones de los equipos.
B8: Cédula 1 Depreciación
B9: MAQUINARIA Y EQUIPO
C10: 2025 | D10: =C10+1 -> 2026 | E10: =D10+1 -> 2027 | F10: =E10+1 -> 2028 | G10: =F10+1 -> 2029 | H10: =G10+1 -> 2030 | I10: =H10+1 -> 2031 | J10: =I10+1 -> 2032 | K10: =J10+1 -> 2033 | ... M10: =L10+1 -> 2035
B11: M-001 | C11: 2800000 | D11: =C11 -> 2800000 | E11: =D11 -> 2800000 | F11: =E11 -> 2800000 | G11: =F11 -> 2800000 | H11: =G11 -> 2800000 | I11: =H11 -> 2800000 | J11: =I11 -> 2800000 | K11: =J11 -> 2800000 | ... M11: =L11 -> 2800000
B12: M-002 | C12: 112000 | D12: =C12 -> 112000 | E12: =D12 -> 112000 | F12: =E12 -> 112000 | G12: =F12 -> 112000 | H12: =G12 -> 112000 | I12: =H12 -> 112000 | J12: =I12 -> 112000 | K12: =J12 -> 112000 | ... M12: =L12 -> 112000
B13: M-003 | C13: 112000 | D13: =C13 -> 112000 | E13: =D13 -> 112000 | F13: =E13 -> 112000 | G13: =F13 -> 112000 | H13: =G13 -> 112000 | I13: =H13 -> 112000 | J13: =I13 -> 112000 | K13: =J13 -> 112000 | ... M13: =L13 -> 112000
B14: M-004 | C14: 112000 | D14: =C14 -> 112000 | E14: =D14 -> 112000 | F14: =E14 -> 112000 | G14: =F14 -> 112000 | H14: =G14 -> 112000 | I14: =H14 -> 112000 | J14: =I14 -> 112000 | K14: =J14 -> 112000 | ... M14: =L14 -> 112000
B15: M-005 | C15: 112000 | D15: =C15 -> 112000 | E15: =D15 -> 112000 | F15: =E15 -> 112000 | G15: =F15 -> 112000 | H15: =G15 -> 112000 | I15: =H15 -> 112000 | J15: =I15 -> 112000 | K15: =J15 -> 112000 | ... M15: =L15 -> 112000
B16: M-006 | C16: 112000 | D16: =C16 -> 112000 | E16: =D16 -> 112000 | F16: =E16 -> 112000 | G16: =F16 -> 112000 | H16: =G16 -> 112000 | I16: =H16 -> 112000 | J16: =I16 -> 112000 | K16: =J16 -> 112000 | ... M16: =L16 -> 112000
B17: M-007 | C17: 2400000 | D17: =C17 -> 2400000 | E17: =D17 -> 2400000 | F17: =E17 -> 2400000 | G17: =F17 -> 2400000 | H17: =G17 -> 2400000 | I17: =H17 -> 2400000 | J17: =I17 -> 2400000 | K17: =J17 -> 2400000 | ... M17: =L17 -> 2400000
B18: Nueva-001 | C18: 2000000 | D18: =C18 -> 2000000 | E18: =D18 -> 2000000 | F18: =E18 -> 2000000 | G18: =F18 -> 2000000 | H18: =G18 -> 2000000 | I18: =H18 -> 2000000 | J18: =I18 -> 2000000 | K18: =J18 -> 2000000 | ... M18: =L18 -> 2000000
B19: Nueva-002 | C19: 300000 | D19: =C19 -> 300000 | E19: =D19 -> 300000 | F19: =E19 -> 300000 | G19: =F19 -> 300000 | H19: =G19 -> 300000 | I19: =H19 -> 300000 | J19: =I19 -> 300000 | K19: =J19 -> 300000 | ... M19: =L19 -> 300000
B20: Nueva-003 | C20: 0 | D20: =C20 -> 0 | E20: 0 | F20: =E20 -> 0 | G20: =F20 -> 0 | H20: =G20 -> 0 | I20: =H20 -> 0 | J20: =I20 -> 0 | K20: =J20 -> 0 | L20: =K20 -> 0 | M20: =L20 -> 0
B21: Nueva-004 | C21: 0 | D21: =C21 -> 0 | E21: =D21 -> 0 | F21: =E21 -> 0 | G21: =F21 -> 0 | H21: =G21 -> 0 | I21: =H21 -> 0 | J21: =I21 -> 0 | K21: =J21 -> 0 | ... M21: =L21 -> 0
B22: Nueva-005 | C22: 0 | D22: =C22 -> 0 | E22: =D22 -> 0 | F22: =E22 -> 0 | G22: =F22 -> 0 | H22: =G22 -> 0 | I22: =H22 -> 0 | J22: =I22 -> 0 | K22: =J22 -> 0 | ... M22: =L22 -> 0
B23: Nueva-006 | C23: 0 | D23: =C23 -> 0 | E23: =D23 -> 0 | F23: =E23 -> 0 | G23: =F23 -> 0 | H23: =G23 -> 0 | I23: =H23 -> 0 | J23: =I23 -> 0 | K23: =J23 -> 0 | ... M23: =L23 -> 0
B25: Total | C25: =SUM(C11:C24) -> 8060000 | D25: =SUM(D11:D24) -> 8060000 | E25: =SUM(E11:E24) -> 8060000 | F25: =SUM(F11:F24) -> 8060000 | G25: =SUM(G11:G24) -> 8060000 | H25: =SUM(H11:H24) -> 8060000 | I25: =SUM(I11:I24) -> 8060000 | J25: =SUM(J11:J24) -> 8060000 | ... M25: =SUM(M11:M24) -> 8060000
B26: Depreciación | C26: =C25*Premisas!B28 -> 806000 | D26: =D25*Premisas!C28 -> 806000 | E26: =E25*Premisas!D28 -> 806000 | F26: =F25*Premisas!E28 -> 806000 | G26: =G25*Premisas!F28 -> 806000 | H26: =H25*Premisas!G28 -> 806000 | I26: =I25*Premisas!H28 -> 806000 | J26: =J25*Premisas!I28 -> 806000 | ... M26: =M25*Premisas!L28 -> 806000
B28: EQUIPO DE TRANSPORTE.
C29: 2025 | D29: 2025 | E29: 2026 | F29: 2027 | G29: 2028 | H29: 2029 | I29: 2030 | J29: 2031 | K29: 2032 | L29: 2033 | M29: 2034
B30: Auto-1 | C30: 300000 | D30: =C30 -> 300000 | E30: =D30 -> 300000 | F30: =E30 -> 300000 | G30: =F30 -> 300000 | H30: =G30 -> 300000 | I30: =H30 -> 300000 | J30: =I30 -> 300000 | K30: =J30 -> 300000 | ... M30: =L30 -> 300000
B31: Auto-2 | C31: 70000 | D31: =C31 -> 70000 | E31: =D31 -> 70000 | F31: =E31 -> 70000 | G31: =F31 -> 70000 | H31: =G31 -> 70000 | I31: =H31 -> 70000 | J31: =I31 -> 70000 | K31: =J31 -> 70000 | ... M31: =L31 -> 70000
B32: Auto-3 | C32: 70000 | D32: =C32 -> 70000 | E32: =D32 -> 70000 | F32: =E32 -> 70000 | G32: =F32 -> 70000 | H32: =G32 -> 70000 | I32: =H32 -> 70000 | J32: =I32 -> 70000 | K32: =J32 -> 70000 | ... M32: =L32 -> 70000
B33: Auto-4 | C33: 0 | D33: =C33 -> 0 | E33: =D33 -> 0 | F33: =E33 -> 0 | G33: =F33 -> 0 | H33: =G33 -> 0 | I33: =H33 -> 0 | J33: =I33 -> 0 | K33: =J33 -> 0 | ... M33: =L33 -> 0
B34: Camion-1 | C34: 400000 | D34: =C34 -> 400000 | E34: =D34 -> 400000 | F34: =E34 -> 400000 | G34: =F34 -> 400000 | H34: =G34 -> 400000 | I34: =H34 -> 400000 | J34: =I34 -> 400000 | K34: =J34 -> 400000 | ... M34: =L34 -> 400000
B35: Camion-2 | C35: 600000 | D35: =C35 -> 600000 | E35: =D35 -> 600000 | F35: =E35 -> 600000 | G35: =F35 -> 600000 | H35: =G35 -> 600000 | I35: =H35 -> 600000 | J35: =I35 -> 600000 | K35: =J35 -> 600000 | ... M35: =L35 -> 600000
B36: Camion-3 | D36: =C36 -> 0 | E36: =D36 -> 0 | F36: =E36 -> 0 | G36: =F36 -> 0 | H36: =G36 -> 0 | I36: =H36 -> 0 | J36: =I36 -> 0 | K36: =J36 -> 0 | ... M36: =L36 -> 0
B37: Camion-4 | C37: 0 | D37: =C37 -> 0 | E37: =D37 -> 0 | F37: =E37 -> 0 | G37: =F37 -> 0 | H37: =G37 -> 0 | I37: =H37 -> 0 | J37: =I37 -> 0 | K37: =J37 -> 0 | ... M37: =L37 -> 0
B38: Nuevo-1 | C38: 0 | D38: =C38 -> 0 | E38: =D38 -> 0 | F38: =E38 -> 0 | G38: =F38 -> 0 | H38: =G38 -> 0 | I38: =H38 -> 0 | J38: =I38 -> 0 | K38: =J38 -> 0 | ... M38: =L38 -> 0
B39: Nuevo-2 | C39: 0 | D39: =C39 -> 0 | E39: =D39 -> 0 | F39: =E39 -> 0 | G39: =F39 -> 0 | H39: =G39 -> 0 | I39: =H39 -> 0 | J39: =I39 -> 0 | K39: =J39 -> 0 | ... M39: =L39 -> 0
B40: Nuevo-3 | C40: 0 | D40: =C40 -> 0 | E40: =D40 -> 0 | F40: =E40 -> 0 | G40: =F40 -> 0 | H40: =G40 -> 0 | I40: =H40 -> 0 | J40: =I40 -> 0 | K40: =J40 -> 0 | ... M40: =L40 -> 0
B41: Nuevo-4 | C41: 0 | D41: =C41 -> 0 | E41: =D41 -> 0 | F41: =E41 -> 0 | G41: =F41 -> 0 | H41: =G41 -> 0 | I41: =H41 -> 0 | J41: =I41 -> 0 | K41: =J41 -> 0 | ... M41: =L41 -> 0
B42: Nuevo-5 | C42: 0 | D42: =C42 -> 0 | E42: =D42 -> 0 | F42: =E42 -> 0 | G42: =F42 -> 0 | H42: =G42 -> 0 | I42: =H42 -> 0 | J42: =I42 -> 0 | K42: =J42 -> 0 | ... M42: =L42 -> 0
B43: Nuevo-6 | C43: 0 | D43: =C43 -> 0 | E43: =D43 -> 0 | F43: =E43 -> 0 | G43: =F43 -> 0 | H43: =G43 -> 0 | I43: =H43 -> 0 | J43: =I43 -> 0 | K43: =J43 -> 0 | ... M43: =L43 -> 0
B44: Nuevo-7 | C44: 0 | D44: =C44 -> 0 | E44: =D44 -> 0 | F44: =E44 -> 0 | G44: =F44 -> 0 | H44: =G44 -> 0 | I44: =H44 -> 0 | J44: =I44 -> 0 | K44: =J44 -> 0 | ... M44: =L44 -> 0
B46: TOTAL | C46: =SUM(C30:C45) -> 1440000 | D46: =SUM(D30:D45) -> 1440000 | E46: =SUM(E30:E45) -> 1440000 | F46: =SUM(F30:F45) -> 1440000 | G46: =SUM(G30:G45) -> 1440000 | H46: =SUM(H30:H45) -> 1440000 | I46: =SUM(I30:I45) -> 1440000 | J46: =SUM(J30:J45) -> 1440000 | ... M46: =SUM(M30:M45) -> 1440000
B47: Depreciación | C47: =C46*Premisas!B29 -> 288000 | D47: =D46*Premisas!C29 -> 288000 | E47: =E46*Premisas!D29 -> 288000 | F47: =F46*Premisas!E29 -> 288000 | G47: =G46*Premisas!F29 -> 288000 | H47: =H46*Premisas!G29 -> 288000 | I47: =I46*Premisas!H29 -> 288000 | J47: =J46*Premisas!I29 -> 288000 | ... M47: =M46*Premisas!L29 -> 288000
B50: Cédula 1 Depreciación
B51: EDIFICIOS.
...

Sheet Financiamiento
A1: Monto | B1: =Egresos!B215 -> 41098700 | C1: Periodos | D1: 60
A2: Tasa | B2: =[2]Premisas!B4 -> 0.16
A4: 2025 | B4: 1 | C4: 2 | D4: 3 | E4: 4 | F4: 5 | G4: 6 | H4: 7 | I4: 8 | J4: 9 | K4: 10 | L4: 11 | M4: 12 | N4: Total Año 1
A5: Monto | B5: =B1-B6 -> 40413721 | C5: =B5-B6 -> 39728743 | D5: =C5-C6 -> 39043765 | E5: =D5-D6 -> 38358786 | F5: =E5-E6 -> 37673808 | G5: =F5-F6 -> 36988830 | H5: =G5-G6 -> 36303851 | I5: =H5-H6 -> 35618873 | J5: =I5-I6 -> 34933895 | ... M5: =L5-L6 -> 32878960 | N5: =M5 -> 32878960
A6: Amortizacion | B6: =B1/D1 -> 684978.33 | C6: =B6 -> 684978.33 | D6: =C6 -> 684978.33 | E6: =D6 -> 684978.33 | F6: =E6 -> 684978.33 | G6: =F6 -> 684978.33 | H6: =G6 -> 684978.33 | I6: =H6 -> 684978.33 | J6: =I6 -> 684978.33 | ... M6: =L6 -> 684978.33 | N6: =SUM(B6:M6) -> 8219740 | O6: =N5+N6 -> 41098700
A7: Interés | B7: =$B$2/12*B1 -> 547982.66 | C7: =$B$2/12*B5 -> 538849.62 | D7: =$B$2/12*C5 -> 529716.58 | E7: =$B$2/12*D5 -> 520583.53 | F7: =$B$2/12*E5 -> 511450.49 | G7: =$B$2/12*F5 -> 502317.44 | H7: =$B$2/12*G5 -> 493184.4 | I7: =$B$2/12*H5 -> 484051.35 | J7: =$B$2/12*I5 -> 474918.31 | ... M7: =$B$2/12*L5 -> 447519.18 | N7: =SUM(B7:M7) -> 5973011
A8: Total | B8: =SUM(B6:B7) -> 1232961 | C8: =SUM(C6:C7) -> 1223827.9 | D8: =SUM(D6:D7) -> 1214694.9 | E8: =SUM(E6:E7) -> 1205561.9 | F8: =SUM(F6:F7) -> 1196428.8 | G8: =SUM(G6:G7) -> 1187295.8 | H8: =SUM(H6:H7) -> 1178162.7 | I8: =SUM(I6:I7) -> 1169029.7 | ... M8: =SUM(M6:M7) -> 1132497.5 | N8: =SUM(B8:M8) -> 14192751
A10: =A4+1 -> 2026 | B10: =M4+1 -> 13 | C10: =B10+1 -> 14 | D10: =C10+1 -> 15 | E10: =D10+1 -> 16 | F10: =E10+1 -> 17 | G10: =F10+1 -> 18 | H10: =G10+1 -> 19 | I10: =H10+1 -> 20 | J10: =I10+1 -> 21 | ... M10: =L10+1 -> 24 | N10: Total Año 2
A11: Monto | B11: =M5-B12 -> 32193982 | C11: =B11-B12 -> 31509003 | D11: =C11-C12 -> 30824025 | E11: =D11-D12 -> 30139047 | F11: =E11-E12 -> 29454068 | G11: =F11-F12 -> 28769090 | H11: =G11-G12 -> 28084112 | I11: =H11-H12 -> 27399133 | J11: =I11-I12 -> 26714155 | ... M11: =L11-L12 -> 24659220 | N11: =M11 -> 24659220
A12: Amortizacion | B12: =M6 -> 684978.33 | C12: =B12 -> 684978.33 | D12: =C12 -> 684978.33 | E12: =D12 -> 684978.33 | F12: =E12 -> 684978.33 | G12: =F12 -> 684978.33 | H12: =G12 -> 684978.33 | I12: =H12 -> 684978.33 | J12: =I12 -> 684978.33 | ... M12: =L12 -> 684978.33 | N12: =SUM(B12:M12) -> 8219740 | O12: =N11+N12 -> 32878960 | P12: =N5-O12 -> 0
A13: Interés | B13: =$B$2/12*M5 -> 438386.13 | C13: =$B$2/12*B11 -> 429253.09 | D13: =$B$2/12*C11 -> 420120.04 | E13: =$B$2/12*D11 -> 410987 | F13: =$B$2/12*E11 -> 401853.95 | G13: =$B$2/12*F11 -> 392720.91 | H13: =$B$2/12*G11 -> 383587.86 | I13: =$B$2/12*H11 -> 374454.82 | J13: =$B$2/12*I11 -> 365321.78 | ... M13: =$B$2/12*L11 -> 337922.64 | N13: =SUM(B13:M13) -> 4657852.6
A14: Total | B14: =SUM(B12:B13) -> 1123364.5 | C14: =SUM(C12:C13) -> 1114231.4 | D14: =SUM(D12:D13) -> 1105098.4 | E14: =SUM(E12:E13) -> 1095965.3 | F14: =SUM(F12:F13) -> 1086832.3 | G14: =SUM(G12:G13) -> 1077699.2 | H14: =SUM(H12:H13) -> 1068566.2 | I14: =SUM(I12:I13) -> 1059433.2 | ... M14: =SUM(M12:M13) -> 1022901 | N14: =SUM(B14:M14) -> 12877593
A16: =A10+1 -> 2027 | B16: =M10+1 -> 25 | C16: =B16+1 -> 26 | D16: =C16+1 -> 27 | E16: =D16+1 -> 28 | F16: =E16+1 -> 29 | G16: =F16+1 -> 30 | H16: =G16+1 -> 31 | I16: =H16+1 -> 32 | J16: =I16+1 -> 33 | ... M16: =L16+1 -> 36
A17: Monto | B17: =N11-M12 -> 23974242 | C17: =B17-C18 -> 23289263 | D17: =C17-D18 -> 22604285 | E17: =D17-E18 -> 21919307 | F17: =E17-F18 -> 21234328 | G17: =F17-G18 -> 20549350 | H17: =G17-H18 -> 19864372 | I17: =H17-I18 -> 19179393 | J17: =I17-J18 -> 18494415 | ... M17: =L17-M18 -> 16439480 | N17: =M17 -> 16439480 | O17: =N17+N18 -> 24659220 | P17: =N11-O17 -> 0
A18: Amortizacion | B18: =B12 -> 684978.33 | C18: =B18 -> 684978.33 | D18: =C18 -> 684978.33 | E18: =D18 -> 684978.33 | F18: =E18 -> 684978.33 | G18: =F18 -> 684978.33 | H18: =G18 -> 684978.33 | I18: =H18 -> 684978.33 | J18: =I18 -> 684978.33 | ... M18: =L18 -> 684978.33 | N18: =SUM(B18:M18) -> 8219740
A19: Interés | B19: =$B$2/12*M11 -> 328789.6 | C19: =$B$2/12*B17 -> 319656.55 | D19: =$B$2/12*C17 -> 310523.51 | E19: =$B$2/12*D17 -> 301390.47 | F19: =$B$2/12*E17 -> 292257.42 | G19: =$B$2/12*F17 -> 283124.38 | H19: =$B$2/12*G17 -> 273991.33 | I19: =$B$2/12*H17 -> 264858.29 | J19: =$B$2/12*I17 -> 255725.24 | ... M19: =$B$2/12*L17 -> 228326.11 | N19: =SUM(B19:M19) -> 3342694.2
A20: Total | B20: =SUM(B18:B19) -> 1013767.9 | C20: =SUM(C18:C19) -> 1004634.9 | D20: =SUM(D18:D19) -> 995501.84 | E20: =SUM(E18:E19) -> 986368.79 | F20: =SUM(F18:F19) -> 977235.75 | G20: =SUM(G18:G19) -> 968102.71 | H20: =SUM(H18:H19) -> 958969.66 | I20: =SUM(I18:I19) -> 949836.62 | ... M20: =SUM(M18:M19) -> 913304.44 | N20: =SUM(B20:M20) -> 11562434
A22: =A16+1 -> 2028 | B22: =M16+1 -> 37 | C22: =B22+1 -> 38 | D22: =C22+1 -> 39 | E22: =D22+1 -> 40 | F22: =E22+1 -> 41 | G22: =F22+1 -> 42 | H22: =G22+1 -> 43 | I22: =H22+1 -> 44 | J22: =I22+1 -> 45 | ... M22: =L22+1 -> 48
A23: Monto | B23: =N17-B24 -> 15754502 | C23: =B23-C24 -> 15069523 | D23: =C23-D24 -> 14384545 | E23: =D23-E24 -> 13699567 | F23: =E23-F24 -> 13014588 | G23: =F23-G24 -> 12329610 | H23: =G23-H24 -> 11644632 | I23: =H23-I24 -> 10959653 | J23: =I23-J24 -> 10274675 | ... M23: =L23-M24 -> 8219740 | N23: =M23 -> 8219740 | O23: =N23+N24 -> 16439480 | P23: =N17-O23 -> 0
A24: Amortizacion | B24: =B18 -> 684978.33 | C24: =C18 -> 684978.33 | D24: =D18 -> 684978.33 | E24: =E18 -> 684978.33 | F24: =F18 -> 684978.33 | G24: =G18 -> 684978.33 | H24: =H18 -> 684978.33 | I24: =I18 -> 684978.33 | ... M24: =M18 -> 684978.33 | N24: =SUM(B24:M24) -> 8219740
A25: Interés | B25: =$B$2/12*M17 -> 219193.07 | C25: =$B$2/12*B23 -> 210060.02 | D25: =$B$2/12*C23 -> 200926.98 | E25: =$B$2/12*D23 -> 191793.93 | F25: =$B$2/12*E23 -> 182660.89 | G25: =$B$2/12*F23 -> 173527.84 | H25: =$B$2/12*G23 -> 164394.8 | I25: =$B$2/12*H23 -> 155261.75 | J25: =$B$2/12*I23 -> 146128.71 | ... M25: =$B$2/12*L23 -> 118729.58 | N25: =SUM(B25:M25) -> 2027535.9
A26: Total | B26: =SUM(B24:B25) -> 904171.4 | C26: =SUM(C24:C25) -> 895038.35 | D26: =SUM(D24:D25) -> 885905.31 | E26: =SUM(E24:E25) -> 876772.26 | F26: =SUM(F24:F25) -> 867639.22 | G26: =SUM(G24:G25) -> 858506.17 | H26: =SUM(H24:H25) -> 849373.13 | I26: =SUM(I24:I25) -> 840240.08 | ... M26: =SUM(M24:M25) -> 803707.91 | N26: =SUM(B26:M26) -> 10247276
A28: =A22+1 -> 2029 | B28: =M22+1 -> 49 | C28: =B28+1 -> 50 | D28: =C28+1 -> 51 | E28: =D28+1 -> 52 | F28: =E28+1 -> 53 | G28: =F28+1 -> 54 | H28: =G28+1 -> 55 | I28: =H28+1 -> 56 | J28: =I28+1 -> 57 | ... M28: =L28+1 -> 60
A29: Monto | B29: =M23-M24 -> 7534761.6 | C29: =B29-B30 -> 6849783.3 | D29: =C29-C30 -> 6164805 | E29: =D29-D30 -> 5479826.6 | F29: =E29-E30 -> 4794848.3 | G29: =F29-F30 -> 4109870 | H29: =G29-G30 -> 3424891.6 | I29: =H29-H30 -> 2739913.3 | J29: =I29-I30 -> 2054935 | ... M29: =L29-L30 -> -2.4912879e-08 | N29: =M29 -> -2.4912879e-08
A30: Amortizacion | B30: =B18 -> 684978.33 | C30: =C24 -> 684978.33 | D30: =C30 -> 684978.33 | E30: =D30 -> 684978.33 | F30: =E30 -> 684978.33 | G30: =F30 -> 684978.33 | H30: =G30 -> 684978.33 | I30: =H30 -> 684978.33 | J30: =I30 -> 684978.33 | K30: =J30 -> 684978.33 | ... M30: =L30 -> 684978.33 | N30: =SUM(B30:M30) -> 8219740
A31: Interés | B31: =B29*[1]Premisas!$F$5/12 -> 150695.23 | C31: =C29*[1]Premisas!$F$5/12 -> 136995.67 | D31: =D29*[1]Premisas!$F$5/12 -> 123296.1 | E31: =E29*[1]Premisas!$F$5/12 -> 109596.53 | F31: =F29*[1]Premisas!$F$5/12 -> 95896.966 | G31: =G29*[1]Premisas!$F$5/12 -> 82197.4 | H31: =H29*[1]Premisas!$F$5/12 -> 68497.833 | I31: =I29*[1]Premisas!$F$5/12 -> 54798.266 | ... M31: =M29*[1]Premisas!$F$5/12 -> -4.9825758e-10 | N31: =SUM(B31:M31) -> 904171.4
A32: Total | B32: =SUM(B30:B31) -> 835673.56 | C32: =SUM(C30:C31) -> 821974 | D32: =SUM(D30:D31) -> 808274.43 | E32: =SUM(E30:E31) -> 794574.86 | F32: =SUM(F30:F31) -> 780875.3 | G32: =SUM(G30:G31) -> 767175.73 | H32: =SUM(H30:H31) -> 753476.16 | I32: =SUM(I30:I31) -> 739776.6 | ... M32: =SUM(M30:M31) -> 684978.33 | N32: =SUM(B32:M32) -> 9123911.4
A34: =A28+1 -> 2030
A35: Monto
A36: Amortizacion
A37: Interés
A38: Total
A40: =A34+1 -> 2031
A41: Monto
A42: Amortizacion
A43: Interés
A44: Total
A46: =A40+1 -> 2032
A47: Monto
A48: Amortizacion
...

Sheet Egresos
A3: MOD Operador | B3: Porcentaje | C3: Percepción | E3: MOID Materiales | F3: Porcentaje | G3: Percepción | I3: MOID Técnico Pruebas | J3: Porcentaje | K3: Percepción | M3: MOID Almacen | N3: Porcentaje | O3: Percepción
A4: Salario base | C4: 12000 | E4: Salario base | G4: 10000 | I4: Salario base | K4: 15000 | M4: Salario base | O4: 15000
A5: IMSS | B5: 0.03 | C5: =C4*B5 -> 360 | E5: IMSS | F5: 0.03 | G5: =G4*F5 -> 300 | I5: IMSS | J5: 0.03 | K5: =K4*J5 -> 450 | M5: IMSS | N5: 0.03 | O5: =O4*N5 -> 450
A6: Infonavit | B6: 0.2 | C6: =C4*B6 -> 2400 | E6: Infonavit | F6: 0.2 | G6: =G4*F6 -> 2000 | I6: Infonavit | J6: 0.2 | K6: =K4*J6 -> 3000 | M6: Infonavit | N6: 0.2 | O6: =O4*N6 -> 3000
A7: Vales de despensa | B7: 0.13 | C7: =C4*B7 -> 1560 | E7: Vales de despensa | F7: 0.13 | G7: =G4*F7 -> 1300 | I7: Vales de despensa | J7: 0.13 | K7: =K4*J7 -> 1950 | M7: Vales de despensa | N7: 0.13 | O7: =O4*N7 -> 1950
A8: Prima Vacacional | E8: Prima Vacacional | I8: Prima Vacacional | M8: Prima Vacacional
A9: Aguinaldo | B9: 0.288461 | C9: =(C4/30)*B9 -> 115.3844 | E9: Aguinaldo | F9: 0.288461 | G9: =(G4/30)*F9 -> 96.153667 | I9: Aguinaldo | J9: 0.288461 | K9: =(K4/30)*J9 -> 144.2305 | M9: Aguinaldo | N9: 0.288461 | O9: =(O4/30)*N9 -> 144.2305
A10: Fondo de Ahorro | B10: 0.07 | C10: =C4*B10 -> 840 | E10: Fondo de Ahorro | F10: 0.07 | G10: =G4*F10 -> 700 | I10: Fondo de Ahorro | J10: 0.07 | K10: =K4*J10 -> 1050 | M10: Fondo de Ahorro | N10: 0.07 | O10: =O4*N10 -> 1050
A11: Comedor | B11: 0.02 | C11: =C4*B11 -> 240 | E11: Comedor | F11: 0.02 | G11: =G4*F11 -> 200 | I11: Comedor | J11: 0.02 | K11: =K4*J11 -> 300 | M11: Comedor | N11: 0.02 | O11: =O4*N11 -> 300
A12: ISR | B12: 0.16 | C12: =C4*B12 -> 1920 | E12: ISR | F12: 0.1088 | G12: =G4*F12 -> 1088 | I12: ISR | J12: 0.1792 | K12: =K4*J12 -> 2688 | M12: ISR | N12: 0.1792 | O12: =O4*N12 -> 2688
C13: =SUM(C5:C11) -> 5515.3844 | G13: =SUM(G5:G11) -> 4596.1537 | K13: =SUM(K5:K11) -> 6894.2305 | O13: =SUM(O5:O11) -> 6894.2305
A14: Salario Integrado | C14: =C4+C13 -> 17515.384 | E14: Salario Integrado | G14: =G4+G13 -> 14596.154 | I14: Salario Integrado | K14: =K4+K13 -> 21894.23 | M14: Salario Integrado | O14: =O4+O13 -> 21894.23
A17: MOD Supervisor | B17: Porcentaje | C17: Percepción | E17: MOID Técnico Calidad | F17: Porcentaje | G17: Percepción | I17: MOID Técnico Producto | J17: Porcentaje | K17: Percepción | M17: MOID Técnico Logística | N17: Porcentaje | O17: Percepción
A18: Salario base | C18: 15000 | E18: Salario base | G18: 16500 | I18: Salario base | K18: 16500 | M18: Salario base | O18: 16500
A19: IMSS | B19: 0.03 | C19: =C18*B19 -> 450 | E19: IMSS | F19: 0.03 | G19: =G18*F19 -> 495 | I19: IMSS | J19: 0.03 | K19: =K18*J19 -> 495 | M19: IMSS | N19: 0.03 | O19: =O18*N19 -> 495
A20: Infonavit | B20: 0.2 | C20: =C18*B20 -> 3000 | E20: Infonavit | F20: 0.2 | G20: =G18*F20 -> 3300 | I20: Infonavit | J20: 0.2 | K20: =K18*J20 -> 3300 | M20: Infonavit | N20: 0.2 | O20: =O18*N20 -> 3300
A21: Vales de despensa | B21: 0.13 | C21: =C18*B21 -> 1950 | E21: Vales de despensa | F21: 0.13 | G21: =G18*F21 -> 2145 | I21: Vales de despensa | J21: 0.13 | K21: =K18*J21 -> 2145 | M21: Vales de despensa | N21: 0.13 | O21: =O18*N21 -> 2145
A22: Prima Vacacional | E22: Prima Vacacional | I22: Prima Vacacional | M22: Prima Vacacional
A23: Aguinaldo | B23: 0.288461 | C23: =(C18/30)*B23 -> 144.2305 | E23: Aguinaldo | F23: 0.288461 | G23: =(G18/30)*F23 -> 158.65355 | I23: Aguinaldo | J23: 0.288461 | K23: =(K18/30)*J23 -> 158.65355 | M23: Aguinaldo | N23: 0.288461 | O23: =(O18/30)*N23 -> 158.65355
A24: Fondo de Ahorro | B24: 0.07 | C24: =C18*B24 -> 1050 | E24: Fondo de Ahorro | F24: 0.07 | G24: =G18*F24 -> 1155 | I24: Fondo de Ahorro | J24: 0.07 | K24: =K18*J24 -> 1155 | M24: Fondo de Ahorro | N24: 0.07 | O24: =O18*N24 -> 1155
A25: Comedor | B25: 0.02 | C25: =C18*B25 -> 300 | E25: Comedor | F25: 0.02 | G25: =G18*F25 -> 330 | I25: Comedor | J25: 0.02 | K25: =K18*J25 -> 330 | M25: Comedor | N25: 0.02 | O25: =O18*N25 -> 330
A26: ISR | B26: 0.1792 | E26: ISR | F26: 0.2136 | G26: =F26*G18 -> 3524.4 | I26: ISR | J26: 0.2136 | K26: =J26*K18 -> 3524.4 | M26: ISR | N26: 0.2136 | O26: =N26*O18 -> 3524.4
C27: =SUM(C19:C25) -> 6894.2305 | G27: =SUM(G19:G25) -> 7583.6535 | K27: =SUM(K19:K25) -> 7583.6535 | O27: =SUM(O19:O25) -> 7583.6535
A28: Salario Integrado | C28: =C18+C27 -> 21894.23 | E28: Salario Integrado | G28: =G18+G27 -> 24083.654 | I28: Salario Integrado | K28: =K18+K27 -> 24083.654 | M28: Salario Integrado | O28: =O18+O27 -> 24083.654
A31: IM Ingeniero Procesos | B31: Porcentaje | C31: Percepción | E31: IM Ingeniero de Calidad | F31: Porcentaje | G31: Percepción | I31: Ingeniero de Producto | J31: Porcentaje | K31: Percepción | M31: Ingeniero de Mtto | N31: Porcentaje | O31: Percepción
A32: Salario base | C32: 21000 | E32: Salario base | G32: 21000 | I32: Salario base | K32: 16500 | M32: Salario base | O32: 21000
A33: IMSS | B33: 0.03 | C33: =C32*B33 -> 630 | E33: IMSS | F33: 0.03 | G33: =G32*F33 -> 630 | I33: IMSS | J33: 0.03 | K33: =K32*J33 -> 495 | M33: IMSS | N33: 0.03 | O33: =O32*N33 -> 630
A34: Infonavit | B34: 0.2 | C34: =C32*B34 -> 4200 | E34: Infonavit | F34: 0.2 | G34: =G32*F34 -> 4200 | I34: Infonavit | J34: 0.2 | K34: =K32*J34 -> 3300 | M34: Infonavit | N34: 0.2 | O34: =O32*N34 -> 4200
A35: Vales de despensa | B35: 0.13 | C35: =C32*B35 -> 2730 | E35: Vales de despensa | F35: 0.13 | G35: =G32*F35 -> 2730 | I35: Vales de despensa | J35: 0.13 | K35: =K32*J35 -> 2145 | M35: Vales de despensa | N35: 0.13 | O35: =O32*N35 -> 2730
A36: Prima Vacacional | E36: Prima Vacacional | I36: Prima Vacacional | M36: Prima Vacacional
A37: Aguinaldo | B37: 0.288461 | C37: =(C32/30)*B37 -> 201.9227 | E37: Aguinaldo | F37: 0.288461 | G37: =(G32/30)*F37 -> 201.9227 | I37: Aguinaldo | J37: 0.288461 | K37: =(K32/30)*J37 -> 158.65355 | M37: Aguinaldo | N37: 0.288461 | O37: =(O32/30)*N37 -> 201.9227
A38: Fondo de Ahorro | B38: 0.07 | C38: =C32*B38 -> 1470 | E38: Fondo de Ahorro | F38: 0.07 | G38: =G32*F38 -> 1470 | I38: Fondo de Ahorro | J38: 0.07 | K38: =K32*J38 -> 1155 | M38: Fondo de Ahorro | N38: 0.07 | O38: =O32*N38 -> 1470
A39: Comedor | B39: 0.02 | C39: =C32*B39 -> 420 | E39: Comedor | F39: 0.02 | G39: =G32*F39 -> 420 | I39: Comedor | J39: 0.02 | K39: =K32*J39 -> 330 | M39: Comedor | N39: 0.02 | O39: =O32*N39 -> 420
A40: ISR | B40: 0.2136 | C40: =B40*C32 -> 4485.6 | E40: ISR | F40: 0.2136 | G40: =F40*G32 -> 4485.6 | I40: ISR | J40: 0.2136 | K40: =J40*K32 -> 3524.4 | M40: ISR | N40: 0.2136 | O40: =N40*O32 -> 4485.6
C41: =SUM(C33:C39) -> 9651.9227 | G41: =SUM(G33:G39) -> 9651.9227 | K41: =SUM(K33:K39) -> 7583.6535 | O41: =SUM(O33:O39) -> 9651.9227
A42: Salario Integrado | C42: =C32+C41 -> 30651.923 | E42: Salario Integrado | G42: =G32+G41 -> 30651.923 | I42: Salario Integrado | K42: =K32+K41 -> 24083.654 | M42: Salario Integrado | O42: =O32+O41 -> 30651.923
A45: Gerente de Operaciones | B45: Porcentaje | C45: Percepción
A46: Salario base | C46: 35000
A47: IMSS | B47: 0.03 | C47: =C46*B47 -> 1050
A48: Infonavit | B48: 0.2 | C48: =C46*B48 -> 7000
...

Sheet Ingresos
A2: Precio de Venta Unitario
B4: 2025 | C4: =B4+1 -> 2026 | D4: =C4+1 -> 2027 | E4: =D4+1 -> 2028 | F4: =E4+1 -> 2029 | G4: =F4+1 -> 2030 | H4: =G4+1 -> 2031 | I4: =H4+1 -> 2032 | J4: =I4+1 -> 2033 | ... L4: =K4+1 -> 2035
A5: Materia Prima | B5: =Egresos!B178/Capacidad!E16 -> 7651.2875 | C5: =Egresos!C178/Capacidad!F16 -> 7446.053 | D5: =Egresos!D178/Capacidad!G16 -> 7271.4844 | E5: =Egresos!E178/Capacidad!H16 -> 7518.7149 | F5: =Egresos!F178/Capacidad!I16 -> 7774.3512 | G5: =Egresos!G178/Capacidad!J16 -> 8038.6791 | H5: =Egresos!H178/Capacidad!K16 -> 8311.9942 | I5: =Egresos!I178/Capacidad!L16 -> 8594.602 | ... L5: =Egresos!L178/Capacidad!O16 -> 9501.3953
A6: Mano de Obra Directa | B6: =Egresos!B151/Capacidad!E16 -> 334.98173 | C6: =Egresos!C151/Capacidad!F16 -> 65.290674 | D6: =Egresos!D151/Capacidad!G16 -> 63.093749 | E6: =Egresos!E151/Capacidad!H16 -> 60.971351 | F6: =Egresos!F151/Capacidad!I16 -> 58.920885 | G6: =Egresos!G151/Capacidad!J16 -> 56.937308 | H6: =Egresos!H151/Capacidad!K16 -> 55.021818 | I6: =Egresos!I151/Capacidad!L16 -> 53.170407 | ... L6: =Egresos!L151/Capacidad!O16 -> 50.039873
A7: Mano de Obra Indirecta | B7: =Egresos!B152/Capacidad!E16 -> 108.9238 | C7: =Egresos!C152/Capacidad!F16 -> 21.230137 | D7: =Egresos!D152/Capacidad!G16 -> 20.515778 | E7: =Egresos!E152/Capacidad!H16 -> 19.825652 | F7: =Egresos!F152/Capacidad!I16 -> 19.158915 | G7: =Egresos!G152/Capacidad!J16 -> 18.513929 | H7: =Egresos!H152/Capacidad!K16 -> 17.891081 | I7: =Egresos!I152/Capacidad!L16 -> 17.28907 | ... L7: =Egresos!L152/Capacidad!O16 -> 16.271135
A8: Salarios Ingeniería | B8: =Egresos!B153/Capacidad!E16 -> 125.34447 | C8: =Egresos!C153/Capacidad!F16 -> 24.430661 | D8: =Egresos!D153/Capacidad!G16 -> 23.608609 | E8: =Egresos!E153/Capacidad!H16 -> 22.814444 | F8: =Egresos!F153/Capacidad!I16 -> 22.047194 | G8: =Egresos!G153/Capacidad!J16 -> 21.304973 | H8: =Egresos!H153/Capacidad!K16 -> 20.588229 | I8: =Egresos!I153/Capacidad!L16 -> 19.895463 | ... L8: =Egresos!L153/Capacidad!O16 -> 18.72407
A9: Salarios Administrativos | B9: =Egresos!B154/Capacidad!E16 -> 487.14663 | C9: =Egresos!C154/Capacidad!F16 -> 94.948856 | D9: =Egresos!D154/Capacidad!G16 -> 91.753981 | E9: =Egresos!E154/Capacidad!H16 -> 88.667488 | F9: =Egresos!F154/Capacidad!I16 -> 85.685601 | G9: =Egresos!G154/Capacidad!J16 -> 82.800987 | H9: =Egresos!H154/Capacidad!K16 -> 80.015388 | I9: =Egresos!I154/Capacidad!L16 -> 77.322978 | ... L9: =Egresos!L154/Capacidad!O16 -> 72.770404
A10: Gastos Administrativos | B10: =Egresos!B206/Capacidad!E16 -> 332.25 | C10: =Egresos!C206/Capacidad!F16 -> 64.758238 | D10: =Egresos!D206/Capacidad!G16 -> 62.579229 | E10: =Egresos!E206/Capacidad!H16 -> 60.474139 | F10: =Egresos!F206/Capacidad!I16 -> 58.440394 | G10: =Egresos!G206/Capacidad!J16 -> 56.472993 | H10: =Egresos!H206/Capacidad!K16 -> 54.573123 | I10: =Egresos!I206/Capacidad!L16 -> 52.736811 | ... L10: =Egresos!L206/Capacidad!O16 -> 49.631806
A11: Total Gastos | B11: =SUM(B5:B10) -> 9039.9341 | C11: =SUM(C5:C10) -> 7716.7115 | D11: =SUM(D5:D10) -> 7533.0357 | E11: =SUM(E5:E10) -> 7771.4679 | F11: =SUM(F5:F10) -> 8018.6042 | G11: =SUM(G5:G10) -> 8274.7093 | H11: =SUM(H5:H10) -> 8540.0838 | I11: =SUM(I5:I10) -> 8815.0167 | ... L11: =SUM(L5:L10) -> 9708.8326
A13: Amortización crédito | B13: =Egresos!B219 -> 8219740 | C13: =Egresos!C219 -> 8219740 | D13: =Egresos!D219 -> 8219740 | E13: =Egresos!E219 -> 8219740 | F13: =Egresos!F219 -> 8219740 | G13: =Egresos!G219 -> 0 | H13: =Egresos!H219 -> 0 | I13: =Egresos!I219 -> 0 | ... L13: =Egresos!L219 -> 0
A14: Intereses devengados | B14: =Egresos!B220 -> 5973011 | C14: =Egresos!C220 -> 4657852.6 | D14: =Egresos!D220 -> 3342694.2 | E14: =Egresos!E220 -> 2027535.9 | F14: =Egresos!F220 -> 904171.4
A16: Totas Gastos + Financieros | B16: =B11+B13+B14 -> 14201791 | C16: =C11+C13+C14 -> 12885309 | D16: =D11+D13+D14 -> 11569967 | E16: =E11+E13+E14 -> 10255047 | F16: =F11+F13+F14 -> 9131930 | G16: =G11+G13+G14 -> 8274.7093 | H16: =H11+H13+H14 -> 8540.0838 | I16: =I11+I13+I14 -> 8815.0167 | ... L16: =L11+L13+L14 -> 9708.8326
A18: Precio Utilidad
A19: 0.1 | B19: =B11/(1-$A$19) -> 10044.371 | C19: =C11/(1-$A$19) -> 8574.1239 | D19: =D11/(1-$A$19) -> 8370.0397 | E19: =E11/(1-$A$19) -> 8634.9644 | F19: =F11/(1-$A$19) -> 8909.5602 | G19: =G11/(1-$A$19) -> 9194.1214 | H19: =H11/(1-$A$19) -> 9488.982 | I19: =I11/(1-$A$19) -> 9794.463 | ... L19: =L11/(1-$A$19) -> 10787.592
A20: 0.2 | B20: =B11/(1-$A$20) -> 11299.918 | C20: =C11/(1-$A$20) -> 9645.8894 | D20: =D11/(1-$A$20) -> 9416.2947 | E20: =E11/(1-$A$20) -> 9714.3349 | F20: =F11/(1-$A$20) -> 10023.255 | G20: =G11/(1-$A$20) -> 10343.387 | H20: =H11/(1-$A$20) -> 10675.105 | I20: =I11/(1-$A$20) -> 11018.771 | ... L20: =L11/(1-$A$20) -> 12136.041
A21: 0.3 | B21: =B11/(1-$A$21) -> 12914.192 | C21: =C11/(1-$A$21) -> 11023.874 | D21: =D11/(1-$A$21) -> 10761.48 | E21: =E11/(1-$A$21) -> 11102.097 | F21: =F11/(1-$A$21) -> 11455.149 | G21: =G11/(1-$A$21) -> 11821.013 | H21: =H11/(1-$A$21) -> 12200.12 | I21: =I11/(1-$A$21) -> 12592.881 | ... L21: =L11/(1-$A$21) -> 13869.761
A23: Precio por competitividad | B23: 7700 | C23: =B23*(1+Premisas!C12) -> 7961.8 | D23: =C23*(1+Premisas!D12) -> 8232.5012 | E23: =D23*(1+Premisas!E12) -> 8512.4062 | F23: =E23*(1+Premisas!F12) -> 8801.8281 | G23: =F23*(1+Premisas!G12) -> 9101.0902 | H23: =G23*(1+Premisas!H12) -> 9410.5273 | I23: =H23*(1+Premisas!I12) -> 9730.4852 | J23: =I23*(1+Premisas!J12) -> 10061.322 | ... L23: =K23*(1+Premisas!L12) -> 10757.122
A26: Ventas | B26: 2025 | C26: =B26+1 -> 2026 | D26: =C26+1 -> 2027 | E26: =D26+1 -> 2028 | F26: =E26+1 -> 2029 | G26: =F26+1 -> 2030 | H26: =G26+1 -> 2031 | I26: =H26+1 -> 2032 | J26: =I26+1 -> 2033 | ... L26: =K26+1 -> 2035
A27: Customer Orderes (COs) | B27: =Capacidad!E16 -> 16000 | C27: =Capacidad!F16 -> 84881 | D27: =Capacidad!G16 -> 90823 | E27: =Capacidad!H16 -> 97180 | F27: =Capacidad!I16 -> 103981 | G27: =Capacidad!J16 -> 111262 | H27: =Capacidad!K16 -> 119050 | I27: =Capacidad!L16 -> 127384 | ... L27: =Capacidad!O16 -> 149634
A28: Precio Dron Unitario | B28: =B23 -> 7700 | C28: =C23 -> 7961.8 | D28: =D23 -> 8232.5012 | E28: =E23 -> 8512.4062 | F28: =F23 -> 8801.8281 | G28: =G23 -> 9101.0902 | H28: =H23 -> 9410.5273 | I28: =I23 -> 9730.4852 | ... L28: =L23 -> 10757.122
A29: Total ingreso por venta de Dron | B29: =B27*B28 -> 123200000 | C29: =C27*C28 -> 6.7580555e+08 | D29: =D27*D28 -> 7.4770046e+08 | E29: =E27*E28 -> 8.2723564e+08 | F29: =F27*F28 -> 9.1522288e+08 | G29: =G27*G28 -> 1.0126055e+09 | H29: =H27*H28 -> 1.1203233e+09 | I29: =I27*I28 -> 1.2395081e+09 | ... L29: =L27*L28 -> 1.6096313e+09

Sheet Estado R
A1: Estados de Resultados
B2: 2025 | C2: =B2+1 -> 2026 | D2: =C2+1 -> 2027 | E2: =D2+1 -> 2028 | F2: =E2+1 -> 2029 | G2: =F2+1 -> 2030 | H2: =G2+1 -> 2031 | I2: =H2+1 -> 2032 | J2: =I2+1 -> 2033 | ... L2: =K2+1 -> 2035
A3: VENTAS
A4: Dron Sport Life | B4: =Ingresos!B29 -> 123200000 | C4: =Ingresos!C29 -> 6.7580555e+08 | D4: =Ingresos!D29 -> 7.4770046e+08 | E4: =Ingresos!E29 -> 8.2723564e+08 | F4: =Ingresos!F29 -> 9.1522288e+08 | G4: =Ingresos!G29 -> 1.0126055e+09 | H4: =Ingresos!H29 -> 1.1203233e+09 | I4: =Ingresos!I29 -> 1.2395081e+09 | ... L4: =Ingresos!L29 -> 1.6096313e+09
A6: Ventas Netas | B6: =SUM(B4:B5) -> 123200000 | C6: 1.265829e+08 | D6: =SUM(D4:D5) -> 7.4770046e+08 | E6: =SUM(E4:E5) -> 8.2723564e+08 | F6: =SUM(F4:F5) -> 9.1522288e+08 | G6: =SUM(G4:G5) -> 1.0126055e+09 | H6: =SUM(H4:H5) -> 1.1203233e+09 | I6: =SUM(I4:I5) -> 1.2395081e+09 | J6: =SUM(J4:J5) -> 1.3766303e+09 | K6: =SUM(K4:K5) -> 1.4692003e+09 | L6: =SUM(L4:L5) -> 1.6096313e+09
A8: COSTOS
A9: Costo de Matarias Primas Dron | B9: =Egresos!B178 -> 122420600 | C9: =Egresos!C178 -> 6.3202842e+08 | D9: =Egresos!D178 -> 6.6041803e+08 | E9: =Egresos!E178 -> 7.3066871e+08 | F9: =Egresos!F178 -> 8.0838481e+08 | G9: =Egresos!G178 -> 8.9439951e+08 | H9: =Egresos!H178 -> 9.8954291e+08 | I9: =Egresos!I178 -> 1.0948148e+09 | ... L9: =Egresos!L178 -> 1.4217318e+09
A10: Mano de obra directa y supervisores | B10: =Egresos!B151 -> 5359707.6 | C10: =Egresos!C151 -> 5541937.7 | D10: =Egresos!D151 -> 5730363.6 | E10: =Egresos!E151 -> 5925195.9 | F10: =Egresos!F151 -> 6126652.6 | G10: =Egresos!G151 -> 6334958.8 | H10: =Egresos!H151 -> 6550347.4 | I10: =Egresos!I151 -> 6773059.2 | ... L10: =Egresos!L151 -> 7487666.4
A11: Costo Indirectos Sueldos Manufactura | B11: =Egresos!B152 -> 1742780.7 | C11: =Egresos!C152 -> 1802035.3 | D11: =Egresos!D152 -> 1863304.5 | E11: =Egresos!E152 -> 1926656.8 | F11: =Egresos!F152 -> 1992163.2 | G11: =Egresos!G152 -> 2059896.7 | H11: =Egresos!H152 -> 2129933.2 | I11: =Egresos!I152 -> 2202350.9 | ... L11: =Egresos!L152 -> 2434715.1
A12: Costos Salarios de Ingenieria | B12: =Egresos!B153 -> 2005511.5 | C12: =Egresos!C153 -> 2073698.9 | D12: =Egresos!D153 -> 2144204.7 | E12: =Egresos!E153 -> 2217107.6 | F12: =Egresos!F153 -> 2292489.3 | G12: =Egresos!G153 -> 2370433.9 | H12: =Egresos!H153 -> 2451028.7 | I12: =Egresos!I153 -> 2534363.7 | ... L12: =Egresos!L153 -> 2801757.5
A13: Costos Materiales Indirectos | B13: =B6*Premisas!B24 -> 6160000 | C13: =C6*Premisas!C24 -> 6329145 | D13: =D6*Premisas!D24 -> 37385023 | E13: =E6*Premisas!E24 -> 41361782 | F13: =F6*Premisas!F24 -> 45761144 | G13: =G6*Premisas!G24 -> 50630275 | H13: =H6*Premisas!H24 -> 56016164 | I13: =I6*Premisas!I24 -> 61975406 | ... L13: =L6*Premisas!L24 -> 80481563
A14: Costos Indirectos Producto 2
A15: Costos Indirectos Producto 3
A17: Total de Costos | B17: =SUM(B9:B15) -> 1.376886e+08 | C17: =SUM(C9:C15) -> 6.4777524e+08 | D17: =SUM(D9:D15) -> 7.0754092e+08 | E17: =SUM(E9:E15) -> 7.8209945e+08 | F17: =SUM(F9:F15) -> 8.6455726e+08 | G17: =SUM(G9:G15) -> 9.5579508e+08 | H17: =SUM(H9:H15) -> 1.0566904e+09 | I17: =SUM(I9:I15) -> 1.1683e+09 | ... L17: =SUM(L9:L15) -> 1.5149375e+09
A19: Utilidad Bruta | B19: =B6-B17 -> -14488600 | C19: =C6-C17 -> -5.2119234e+08 | D19: =D6-D17 -> 40159534 | E19: =E6-E17 -> 45136186 | F19: =F6-F17 -> 50665625 | G19: =G6-G17 -> 56810420 | H19: =H6-H17 -> 63632890 | I19: =I6-I17 -> 71208166 | ... L19: =L6-L17 -> 94693779
A21: Gastos de Administración | B21: =Egresos!B154+Egresos!B206 -> 13110346 | C21: =Egresos!C154+Egresos!C206 -> 13556098 | D21: =Egresos!D154+Egresos!D206 -> 14017005 | E21: =Egresos!E154+Egresos!E206 -> 14493583 | F21: =Egresos!F154+Egresos!F206 -> 14986365 | G21: =Egresos!G154+Egresos!G206 -> 15495902 | H21: =Egresos!H154+Egresos!H206 -> 16022762 | I21: =Egresos!I154+Egresos!I206 -> 16567536 | ... L21: =Egresos!L154+Egresos!L206 -> 18315532
A22: Depreciación edificios | B22: =Depreciación.!C65 -> 302650 | C22: =Depreciación.!D65 -> 302650 | D22: =Depreciación.!E65 -> 302650 | E22: =Depreciación.!F65 -> 302650 | F22: =Depreciación.!G65 -> 302650 | G22: =Depreciación.!H65 -> 302650 | H22: =Depreciación.!I65 -> 302650 | I22: =Depreciación.!J65 -> 302650 | ... L22: =Depreciación.!M65 -> 302650
A23: Depreciación equipo transp. | B23: =Depreciación.!C47 -> 288000 | C23: =Depreciación.!D47 -> 288000 | D23: =Depreciación.!E47 -> 288000 | E23: =Depreciación.!F47 -> 288000 | F23: =Depreciación.!G47 -> 288000 | G23: =Depreciación.!H47 -> 288000 | H23: =Depreciación.!I47 -> 288000 | I23: =Depreciación.!J47 -> 288000 | ... L23: =Depreciación.!M47 -> 288000
A24: Depreciación Maquinaria y equipo | B24: =Depreciación.!C26 -> 806000 | C24: =Depreciación.!D26 -> 806000 | D24: =Depreciación.!E26 -> 806000 | E24: =Depreciación.!F26 -> 806000 | F24: =Depreciación.!G26 -> 806000 | G24: =Depreciación.!H26 -> 806000 | H24: =Depreciación.!I26 -> 806000 | I24: =Depreciación.!J26 -> 806000 | ... L24: =Depreciación.!M26 -> 806000
A25: Depreciación equipo computo | B25: =Depreciación.!C85 -> 18474.75 | C25: =Depreciación.!D85 -> 18474.75 | D25: =Depreciación.!E85 -> 18474.75 | E25: =Depreciación.!F85 -> 18474.75 | F25: =Depreciación.!G85 -> 18474.75 | G25: =Depreciación.!H85 -> 18474.75 | H25: =Depreciación.!I85 -> 18474.75 | I25: =Depreciación.!J85 -> 18474.75 | ... L25: =Depreciación.!M85 -> 18474.75
A26: Amortización de seguros
A27: Gastos de Ventas
A28: Gastos de Operación | B28: =SUM(B21:B27) -> 14525471 | C28: =SUM(C21:C27) -> 14971223 | D28: =SUM(D21:D27) -> 15432130 | E28: =SUM(E21:E27) -> 15908708 | F28: =SUM(F21:F27) -> 16401490 | G28: =SUM(G21:G27) -> 16911026 | H28: =SUM(H21:H27) -> 17437887 | I28: =SUM(I21:I27) -> 17982661 | ... L28: =SUM(L21:L27) -> 19730657
A30: Utilidad de Operación | B30: =B19-B28 -> -29014071 | C30: =C19-C28 -> -5.3616356e+08 | D30: =D19-D28 -> 24727404 | E30: =E19-E28 -> 29227478 | F30: =F19-F28 -> 34264135 | G30: =G19-G28 -> 39899393 | H30: =H19-H28 -> 46195003 | I30: =I19-I28 -> 53225505 | ... L30: =L19-L28 -> 74963122
A32: Gastos Financieros | B32: =Egresos!B220 -> 5973011 | C32: =Egresos!C220 -> 4657852.6 | D32: =Egresos!D220 -> 3342694.2 | E32: =Egresos!E220 -> 2027535.9 | F32: =Egresos!F220 -> 904171.4 | G32: =Egresos!G220 -> 0 | H32: =Egresos!H220 -> 0 | I32: =Egresos!I220 -> 0 | ... L32: =Egresos!L220 -> 0
A33: Pago de Crédito | B33: =Egresos!B219 -> 8219740 | C33: =Egresos!C219 -> 8219740 | D33: =Egresos!D219 -> 8219740 | E33: =Egresos!E219 -> 8219740 | F33: =Egresos!F219 -> 8219740 | G33: =Egresos!G219 -> 0 | H33: =Egresos!H219 -> 0 | I33: =Egresos!I219 -> 0 | ... L33: =Egresos!L219 -> 0
A34: Productos Financieros
A36: Utilidad antes de impuestos | B36: =B30-B32-B33+B34 -> -43206822 | C36: =C30-C32-C33+C34 -> -5.4904115e+08 | D36: =D30-D32-D33+D34 -> 13164970 | E36: =E30-E32-E33+E34 -> 18980202 | F36: =F30-F32-F33+F34 -> 25140224 | G36: =G30-G32-G33+G34 -> 39899393 | H36: =H30-H32-H33+H34 -> 46195003 | I36: =I30-I32-I33+I34 -> 53225505 | ... L36: =L30-L32-L33+L34 -> 74963122
A38: I.S.R. y T.P.U. | B38: =IF(B36<0,0,B36*Premisas!B13) -> 0 | C38: =IF(C36<0,0,C36*Premisas!C13) -> 0 | D38: =IF(D36<0,0,D36*Premisas!D13) -> 4476089.8 | E38: =IF(E36<0,0,E36*Premisas!E13) -> 6453268.8 | F38: =IF(F36<0,0,F36*Premisas!F13) -> 8547676.1 | G38: =IF(G36<0,0,G36*Premisas!G13) -> 13565794 | H38: =IF(H36<0,0,H36*Premisas!H13) -> 15706301 | I38: =IF(I36<0,0,I36*Premisas!I13) -> 18096672 | ... M38: =IF(M36<0,0,M36*Premisas!M13) -> 0
A40: Utilidad o perdida del periodo | B40: =B36-B38 -> -43206822 | C40: =C36-C38 -> -5.4904115e+08 | D40: =D36-D38 -> 8688880.3 | E40: =E36-E38 -> 12526934 | F40: =F36-F38 -> 16592548 | G40: =G36-G38 -> 26333600 | H40: =H36-H38 -> 30488702 | I40: =I36-I38 -> 35128833 | ... L40: =L36-L38 -> 49475660
A49: Punto de Equilibrio
A50: Costos Fijos Anuales | D50: Precio de Venta | E50: =Ingresos!B23 -> 7700
A51: Gastos Administrativos | B51: =Egresos!B220 -> 5973011
A52: Salarios | B52: =Egresos!B153+Egresos!B154+Egresos!B152 -> 11542638 | D52: Cantidad de | E52: =B54/(E50-B60) -> 24186.707 | G52: Ingreso de | H52: =B54/((E50-B60)/E50) -> 1.8623764e+08
A53: Pago de Crédito | B53: =Egresos!B219+Egresos!B220 -> 14192751 | D53: Equilibrio | G53: Equilibrio
A54: Total | B54: =SUM(B51:B53) -> 31708400
D56: Beneficio deseado | E56: 500000
A57: Costos Variables Unitarios
A58: BOM (Materia Prima) | B58: =Egresos!B176 -> 6121.03 | D58: Cantidad para | E58: =(B54+E56)/(E50-B60) -> 24568.099 | G58: Ingreso de | H58: =(B54+E56)/((E50-B60)/E50) -> 1.8917436e+08
A59: Mano de Obra Directa | B59: =Egresos!B151/Capacidad!E17 -> 267.98538 | D59: alcazar beneficio | G59: Equilibrio
...

Sheet Flujo
A1: Flujo de Efectivo
A2: Entradas | B2: 2025 | C2: =B2+1 -> 2026 | D2: =C2+1 -> 2027 | E2: =D2+1 -> 2028 | F2: =E2+1 -> 2029 | G2: =F2+1 -> 2030 | H2: =G2+1 -> 2031 | I2: =H2+1 -> 2032 | J2: =I2+1 -> 2033 | ... L2: =K2+1 -> 2035
A3: Saldo Inicial | B3: 1000000 | C3: =B34 -> -18284347 | D3: =C34 -> -16687730 | E3: =D34 -> -6583725.4 | F3: =E34 -> 7358332.9 | G3: =F34 -> 25366005 | H3: =G34 -> 53114730 | I3: =H34 -> 85018557 | J3: =I34 -> 1.2156252e+08 | ... L3: =K34 -> 2.0889509e+08
A4: Ingresos del periodo
A5: Ventas | B5: ='Estado R'!B4 -> 123200000 | C5: ='Estado R'!C4 -> 6.7580555e+08 | D5: ='Estado R'!D4 -> 7.4770046e+08 | E5: ='Estado R'!E4 -> 8.2723564e+08 | F5: ='Estado R'!F4 -> 9.1522288e+08 | G5: ='Estado R'!G4 -> 1.0126055e+09 | H5: ='Estado R'!H4 -> 1.1203233e+09 | I5: ='Estado R'!I4 -> 1.2395081e+09 | ... L5: ='Estado R'!L4 -> 1.6096313e+09
A6: Prestamo a largo plazo. | B6: =Financiamiento!B1 -> 41098700
A7: Prestamos a corto plazo.
A8: Otros Ingresos
A10: Total de entradas | B10: =SUM(B3:B8) -> 1.652987e+08 | C10: =SUM(C3:C8) -> 6.575212e+08 | D10: =SUM(D3:D8) -> 7.3101273e+08 | E10: =SUM(E3:E8) -> 8.2065191e+08 | F10: =SUM(F3:F8) -> 9.2258122e+08 | G10: =SUM(G3:G8) -> 1.0379715e+09 | H10: =SUM(H3:H8) -> 1.173438e+09 | I10: =SUM(I3:I8) -> 1.3245267e+09 | ... L10: =SUM(L3:L8) -> 1.8185264e+09
A12: Salidas
A13: Materias Primas Dron | B13: ='Estado R'!B9 -> 122420600 | C13: ='Estado R'!C9 -> 6.3202842e+08 | D13: ='Estado R'!D9 -> 6.6041803e+08 | E13: ='Estado R'!E9 -> 7.3066871e+08 | F13: ='Estado R'!F9 -> 8.0838481e+08 | G13: ='Estado R'!G9 -> 8.9439951e+08 | H13: ='Estado R'!H9 -> 9.8954291e+08 | I13: ='Estado R'!I9 -> 1.0948148e+09 | ... L13: ='Estado R'!L9 -> 1.4217318e+09
A14: Mano de obra directa y supervisores | B14: ='Estado R'!B10 -> 5359707.6 | C14: ='Estado R'!C10 -> 5541937.7 | D14: ='Estado R'!D10 -> 5730363.6 | E14: ='Estado R'!E10 -> 5925195.9 | F14: ='Estado R'!F10 -> 6126652.6 | G14: ='Estado R'!G10 -> 6334958.8 | H14: ='Estado R'!H10 -> 6550347.4 | I14: ='Estado R'!I10 -> 6773059.2 | ... L14: ='Estado R'!L10 -> 7487666.4
A15: Sueldos Indirectos Manufactura | B15: ='Estado R'!B11 -> 1742780.7 | C15: ='Estado R'!C11 -> 1802035.3 | D15: ='Estado R'!D11 -> 1863304.5 | E15: ='Estado R'!E11 -> 1926656.8 | F15: ='Estado R'!F11 -> 1992163.2 | G15: ='Estado R'!G11 -> 2059896.7 | H15: ='Estado R'!H11 -> 2129933.2 | I15: ='Estado R'!I11 -> 2202350.9 | ... L15: ='Estado R'!L11 -> 2434715.1
A16: Salarios de Ingenieria | B16: ='Estado R'!B12 -> 2005511.5 | C16: ='Estado R'!C12 -> 2073698.9 | D16: ='Estado R'!D12 -> 2144204.7 | E16: ='Estado R'!E12 -> 2217107.6 | F16: ='Estado R'!F12 -> 2292489.3 | G16: ='Estado R'!G12 -> 2370433.9 | H16: ='Estado R'!H12 -> 2451028.7 | I16: ='Estado R'!I12 -> 2534363.7 | ... L16: ='Estado R'!L12 -> 2801757.5
A17: Materiales Indirectos | B17: ='Estado R'!B13 -> 6160000 | C17: ='Estado R'!C13 -> 6329145 | D17: ='Estado R'!D13 -> 37385023 | E17: ='Estado R'!E13 -> 41361782 | F17: ='Estado R'!F13 -> 45761144 | G17: ='Estado R'!G13 -> 50630275 | H17: ='Estado R'!H13 -> 56016164 | I17: ='Estado R'!I13 -> 61975406 | ... L17: ='Estado R'!L13 -> 80481563
A18: Sueldos Administración | B18: =Egresos!B154 -> 7794346.1 | C18: =Egresos!C154 -> 8059353.8 | D18: =Egresos!D154 -> 8333371.9 | E18: =Egresos!E154 -> 8616706.5 | F18: =Egresos!F154 -> 8909674.5 | G18: =Egresos!G154 -> 9212603.5 | H18: =Egresos!H154 -> 9525832 | I18: =Egresos!I154 -> 9849710.3 | ... L18: =Egresos!L154 -> 10888927
A19: Gastos Administración Empresa | B19: =Egresos!B206 -> 5316000 | C19: =Egresos!C206 -> 5496744 | D19: =Egresos!D206 -> 5683633.3 | E19: =Egresos!E206 -> 5876876.8 | F19: =Egresos!F206 -> 6076690.6 | G19: =Egresos!G206 -> 6283298.1 | H19: =Egresos!H206 -> 6496930.3 | I19: =Egresos!I206 -> 6717825.9 | ... L19: =Egresos!L206 -> 7426605.6
A20: Gastos de Venta (Promoción, Patrocinios)
A21: Compra Maquinaria | B21: =Egresos!B210 -> 8060000
A22: Construcción/Compra Edificio | B22: =Egresos!B209 -> 6053000
A23: Obra civil instalación maquinaria | B23: =Egresos!B214 -> 2821000
A24: Compra Equipo de Computo | B24: =Egresos!B211 -> 217350
A25: Compra Equipo de transporte | B25: =Egresos!B212 -> 1440000
A26: Pago de Credito | B26: ='Estado R'!B33 -> 8219740 | C26: ='Estado R'!C33 -> 8219740 | D26: ='Estado R'!D33 -> 8219740 | E26: ='Estado R'!E33 -> 8219740 | F26: ='Estado R'!F33 -> 8219740 | G26: ='Estado R'!G33 -> 0 | H26: ='Estado R'!H33 -> 0 | I26: ='Estado R'!I33 -> 0 | ... L26: ='Estado R'!L33 -> 0
A27: Pago de intereses por credito | B27: ='Estado R'!B32 -> 5973011 | C27: ='Estado R'!C32 -> 4657852.6 | D27: ='Estado R'!D32 -> 3342694.2 | E27: ='Estado R'!E32 -> 2027535.9 | F27: ='Estado R'!F32 -> 904171.4 | G27: ='Estado R'!G32 -> 0 | H27: ='Estado R'!H32 -> 0 | I27: ='Estado R'!I32 -> 0 | ... L27: ='Estado R'!L32 -> 0
